Workbook

Sheet COVER PAGE
J22: EDGELITE TECHNOLOGIES
J23: Seed-Stage Institutional Financial Model
G28: Company Name: | L28: Edgelite Technologies
G29: Industry: | L29: AI Robotics / Autonomous Companion & Logistics Robots
G30: Headquarters: | L30: Lagos, Nigeria
G31: Model Purpose: | L31: Seed round ($2.0M) fundraising model - investor diligence & internal planning
G32: Forecast Period: | L32: 24 months full detail (Yrs 1-2) + Year 3 as a single annualized column
G33: Prepared By: | L33: WILLIAMS EQUITIES - Financial Modeling Practice
G34: Prepared For: | L34: Founders, Board, Prospective Seed Investors
G35: Date: | L35: 27-Aug-2026
G36: Version: | L36: 1.0 - Phase 1 Annual Build
G37: Classification: | L37: Confidential - Draft for Discussion

Sheet COMPANY OVERVIEW
B4: COMPANY OVERVIEW
B6: Business Summary
B8: Founded: | C8: 2027, Lagos, Nigeria
B9: Stage: | C9: Pre-revenue, Seed
B10: Product: | C10: EdgeBot - autonomous AI-powered companion & logistics robot
B11: Segment 1: | C11: Consumer Companion: home assistance, AI interaction, smart-home integration, security monitoring
B12: Segment 2: | C12: Last-Mile Logistics: grocery/package delivery, campus transport, small business logistics
B13: Vision: | C13: "To make intelligent robotic companions as common and essential as smartphones."
B15: Market Opportunity & Funding Objective
B17: Target Market: | C17: Urban African consumer households + last-mile logistics operators; expansion path to broader EM/global consumer robotics
B18: Problem: | C18: Urban delivery is expensive/inefficient; consumer demand for smart-home & personal assistance is underserved by affordable robotics
B19: Funding Objective: | C19: Raise $2.0M Seed to fund product finalization, initial manufacturing scale-up, and go-to-market for EdgeBot Home/Pro/Enterprise
B20: Use of Proceeds: | C20: Engineering & AI R&D (45%), Manufacturing/inventory (25%), Go-to-market (20%), G&A/working capital (10%)

Sheet ASSUMPTIONS
B2: ASSUMPTIONS
B4: Scenario Manager (Downside/Base/Upside toggle) lives here at the top. Every other section below, and every other tab, reads only from the Selected column.
B6: SELECTED SCENARIO | C6: Base | D6: <- Change to Downside / Base / Upside to re-drive the ENTIRE model
B8: Scenario Driver | C8: Downside | D8: Base | E8: Upside | F8: Selected
B9: Inflation Rate (Annual) | C9: 0.2 | D9: 0.12 | E9: 0.08 | F9: =INDEX(C9:E9,MATCH($C$6,$C$8:$E$8,0)) -> 0.12
B10: Wage Inflation Rate (Annual) | C10: 0.15 | D10: 0.1 | E10: 0.06 | F10: =INDEX(C10:E10,MATCH($C$6,$C$8:$E$8,0)) -> 0.1
B11: Unit Sales Growth Rate (Annual, YoY) | C11: 0.25 | D11: 0.5 | E11: 0.8 | F11: =INDEX(C11:E11,MATCH($C$6,$C$8:$E$8,0)) -> 0.5
B12: Customer Adoption Multiplier (Month-1 Traffic/Units) | C12: 0.7 | D12: 1 | E12: 1.3 | F12: =INDEX(C12:E12,MATCH($C$6,$C$8:$E$8,0)) -> 1
B13: Manufacturing Cost Multiplier (Month-1 Cost) | C13: 1.15 | D13: 1 | E13: 0.9 | F13: =INDEX(C13:E13,MATCH($C$6,$C$8:$E$8,0)) -> 1
B14: Pricing Growth Rate (Annual) | C14: 0.02 | D14: 0.03 | E14: 0.05 | F14: =INDEX(C14:E14,MATCH($C$6,$C$8:$E$8,0)) -> 0.03
B15: Marketing Spend Multiplier | C15: 0.8 | D15: 1 | E15: 1.3 | F15: =INDEX(C15:E15,MATCH($C$6,$C$8:$E$8,0)) -> 1
B16: Hiring Pace Multiplier | C16: 0.7 | D16: 1 | E16: 1.3 | F16: =INDEX(C16:E16,MATCH($C$6,$C$8:$E$8,0)) -> 1
B20: Monthly-Equivalent Conversions (used by Customer Acquisition & Cost Build tabs)
B22: Monthly Unit-Growth-Equivalent Rate | C22: =(1+ASSUMPTIONS!$F$11)^(1/12)-1 -> 0.034366083
B23: Organic Traffic Premium Multiplier (goodwill/SEO compounding vs Paid) | C23: 1.3
B24: Monthly Pricing-Growth-Equivalent Rate | C24: =(1+ASSUMPTIONS!$F$14)^(1/12)-1 -> 0.0024662698
B25: Monthly Cost-Inflation-Equivalent Rate | C25: =(1+ASSUMPTIONS!$F$9)^(1/12)-1 -> 0.0094887929
B26: Monthly Wage-Inflation-Equivalent Rate | C26: =(1+ASSUMPTIONS!$F$10)^(1/12)-1 -> 0.0079741404
B28: Funding
B30: Seed Raise Amount ($) | C30: 2000000
B31: Ownership Sold to Investors (%) | C31: 0.15
B32: Post-Money Valuation ($) | C32: =C30/C31 -> 13333333
B33: Pre-Money Valuation ($) | C33: =C32-C30 -> 11333333
B34: Founder Ownership (%) | C34: =1-C31 -> 0.85
B36: Product Pricing & Order Economics — Month 1 Base
B38: Blended Home/Pro Average Order Value ($) | C38: 1100
B39: Enterprise Unit Price ($) | C39: 3000
B40: Blended Home/Pro Unit Manufacturing Cost ($) | C40: 433
B41: Enterprise Unit Manufacturing Cost ($) | C41: 970
B42: Order Fulfillment / Shipping Cost per Order ($) | C42: 25
B44: Customer Acquisition — Month 1 Base
B46: Paid Traffic (clicks/visits), Month 1 | C46: 3000
B47: Organic Traffic (visits), Month 1 | C47: 2000
B48: Paid Conversion Rate, Month 1 | C48: 0.012
B49: Organic Conversion Rate, Month 1 (higher — brand goodwill) | C49: 0.028
B50: Paid Conversion — Monthly Improvement (pp) | C50: 0.0002
B51: Organic Conversion — Monthly Improvement (pp) | C51: 0.0003
B52: Paid Traffic Cost per Click ($), Month 1 | C52: 0.35
B53: Organic Channel Investment ($/mo), Month 1 — content/SEO/community | C53: 2500
B54: Enterprise Deals per Month, Month 1 | C54: 3
...

Sheet CUSTOMER ACQUISITION & REVENUE
B2: CUSTOMER ACQUISITION & REVENUE
D4: 2027 | P4: 2028
C5: Months | D5: 1 | E5: 2 | F5: 3 | G5: =F5+1 -> 4 | H5: =G5+1 -> 5 | I5: =H5+1 -> 6 | J5: =I5+1 -> 7 | K5: =J5+1 -> 8 | L5: =K5+1 -> 9 | M5: =L5+1 -> 10 | N5: =M5+1 -> 11 | ... AA5: =Z5+1 -> 24 | AB5: Year 3 (Annual)
B8: 1. Page Traffic (DTC - Home + Pro)
B9: Paid Traffic (Clicks / Visits) | D9: =ASSUMPTIONS!C46 -> 3000 | E9: =D9*(1+ASSUMPTIONS!$C$22) -> 3103.0982 | F9: =E9*(1+ASSUMPTIONS!$C$22) -> 3209.7396 | G9: =F9*(1+ASSUMPTIONS!$C$22) -> 3320.0458 | H9: =G9*(1+ASSUMPTIONS!$C$22) -> 3434.1427 | I9: =H9*(1+ASSUMPTIONS!$C$22) -> 3552.1608 | J9: =I9*(1+ASSUMPTIONS!$C$22) -> 3674.2346 | K9: =J9*(1+ASSUMPTIONS!$C$22) -> 3800.5037 | L9: =K9*(1+ASSUMPTIONS!$C$22) -> 3931.1121 | ... AA9: =Z9*(1+ASSUMPTIONS!$C$22) -> 6525.736
B10: Organic Traffic (Visits) | D10: =ASSUMPTIONS!C47 -> 2000 | E10: =D10*(1+ASSUMPTIONS!$C$22*ASSUMPTIONS!$C$23) -> 2089.3518 | F10: =E10*(1+ASSUMPTIONS!$C$22*ASSUMPTIONS!$C$23) -> 2182.6955 | G10: =F10*(1+ASSUMPTIONS!$C$22*ASSUMPTIONS!$C$23) -> 2280.2094 | H10: =G10*(1+ASSUMPTIONS!$C$22*ASSUMPTIONS!$C$23) -> 2382.0798 | I10: =H10*(1+ASSUMPTIONS!$C$22*ASSUMPTIONS!$C$23) -> 2488.5014 | J10: =I10*(1+ASSUMPTIONS!$C$22*ASSUMPTIONS!$C$23) -> 2599.6775 | K10: =J10*(1+ASSUMPTIONS!$C$22*ASSUMPTIONS!$C$23) -> 2715.8204 | L10: =K10*(1+ASSUMPTIONS!$C$22*ASSUMPTIONS!$C$23) -> 2837.1522 | ... AA10: =Z10*(1+ASSUMPTIONS!$C$22*ASSUMPTIONS!$C$23) -> 5465.2033
B11: Total Traffic | D11: =SUM(D9:D10) -> 5000 | E11: =SUM(E9:E10) -> 5192.4501 | F11: =SUM(F9:F10) -> 5392.4351 | G11: =SUM(G9:G10) -> 5600.2552 | H11: =SUM(H9:H10) -> 5816.2226 | I11: =SUM(I9:I10) -> 6040.6622 | J11: =SUM(J9:J10) -> 6273.9121 | K11: =SUM(K9:K10) -> 6516.3241 | ... AA11: =SUM(AA9:AA10) -> 11990.939
B13: 2. Conversion Rates (Paid, then Organic)
B14: Paid Conversion Rate | D14: =ASSUMPTIONS!C48 -> 0.012 | E14: =D14+ASSUMPTIONS!$C$50 -> 0.0122 | F14: =E14+ASSUMPTIONS!$C$50 -> 0.0124 | G14: =F14+ASSUMPTIONS!$C$50 -> 0.0126 | H14: =G14+ASSUMPTIONS!$C$50 -> 0.0128 | I14: =H14+ASSUMPTIONS!$C$50 -> 0.013 | J14: =I14+ASSUMPTIONS!$C$50 -> 0.0132 | K14: =J14+ASSUMPTIONS!$C$50 -> 0.0134 | L14: =K14+ASSUMPTIONS!$C$50 -> 0.0136 | ... AA14: =Z14+ASSUMPTIONS!$C$50 -> 0.0166
B15: Organic Conversion Rate (Higher based on Brand's Goodwill Gained) | D15: =ASSUMPTIONS!C49 -> 0.028 | E15: =D15+ASSUMPTIONS!$C$51 -> 0.0283 | F15: =E15+ASSUMPTIONS!$C$51 -> 0.0286 | G15: =F15+ASSUMPTIONS!$C$51 -> 0.0289 | H15: =G15+ASSUMPTIONS!$C$51 -> 0.0292 | I15: =H15+ASSUMPTIONS!$C$51 -> 0.0295 | J15: =I15+ASSUMPTIONS!$C$51 -> 0.0298 | K15: =J15+ASSUMPTIONS!$C$51 -> 0.0301 | L15: =K15+ASSUMPTIONS!$C$51 -> 0.0304 | ... AA15: =Z15+ASSUMPTIONS!$C$51 -> 0.0349
B16: Average (Blended Conversion Rate) | D16: =IFERROR((D9*D14+D10*D15)/D11,0) -> 0.0184 | E16: =IFERROR((E9*E14+E10*E15)/E11,0) -> 0.018678361 | F16: =IFERROR((F9*F14+F10*F15)/F11,0) -> 0.018957273 | G16: =IFERROR((G9*G14+G10*G15)/G11,0) -> 0.019236736 | H16: =IFERROR((H9*H14+H10*H15)/H11,0) -> 0.019516749 | I16: =IFERROR((I9*I14+I10*I15)/I11,0) -> 0.019797313 | J16: =IFERROR((J9*J14+J10*J15)/J11,0) -> 0.020078427 | K16: =IFERROR((K9*K14+K10*K15)/K11,0) -> 0.02036009 | ... AA16: =IFERROR((AA9*AA14+AA10*AA15)/AA11,0) -> 0.024940733
B18: 3. Orders (Home + Pro, Via DTC funnel
B19: Paid Orders | D19: =D9*D14 -> 36 | E19: =E9*E14 -> 37.857799 | F19: =F9*F14 -> 39.800771 | G19: =G9*G14 -> 41.832577 | H19: =H9*H14 -> 43.957027 | I19: =I9*I14 -> 46.17809 | J19: =J9*J14 -> 48.499897 | K19: =K9*K14 -> 50.926749 | ... AA19: =AA9*AA14 -> 108.32722
B20: Organic Orders | D20: =D10*D15 -> 56 | E20: =E10*E15 -> 59.128656 | F20: =F10*F15 -> 62.425091 | G20: =G10*G15 -> 65.898052 | H20: =H10*H15 -> 69.556731 | I20: =I10*I15 -> 73.410792 | J20: =J10*J15 -> 77.470389 | K20: =K10*K15 -> 81.746195 | ... AA20: =AA10*AA15 -> 190.73559
B21: Total DTC Orders | D21: =SUM(D19:D20) -> 92 | E21: =SUM(E19:E20) -> 96.986455 | F21: =SUM(F19:F20) -> 102.22586 | G21: =SUM(G19:G20) -> 107.73063 | H21: =SUM(H19:H20) -> 113.51376 | I21: =SUM(I19:I20) -> 119.58888 | J21: =SUM(J19:J20) -> 125.97029 | K21: =SUM(K19:K20) -> 132.67294 | ... AA21: =SUM(AA19:AA20) -> 299.06281
B23: 4. DTC Order Economics
B24: Average Order Value ($) - Blended Home / Pro | D24: =ASSUMPTIONS!C38 -> 1100 | E24: =D24*(1+ASSUMPTIONS!$C$24) -> 1102.7129 | F24: =E24*(1+ASSUMPTIONS!$C$24) -> 1105.4325 | G24: =F24*(1+ASSUMPTIONS!$C$24) -> 1108.1588 | H24: =G24*(1+ASSUMPTIONS!$C$24) -> 1110.8918 | I24: =H24*(1+ASSUMPTIONS!$C$24) -> 1113.6316 | J24: =I24*(1+ASSUMPTIONS!$C$24) -> 1116.3781 | K24: =J24*(1+ASSUMPTIONS!$C$24) -> 1119.1314 | L24: =K24*(1+ASSUMPTIONS!$C$24) -> 1121.8914 | ... AA24: =Z24*(1+ASSUMPTIONS!$C$24) -> 1164.119
B25: DTC Revenue ($) | D25: =D21*D24 -> 101200 | E25: =E21*E24 -> 106948.21 | F25: =F21*F24 -> 113003.79 | G25: =G21*G24 -> 119382.64 | H25: =H21*H24 -> 126101.5 | I25: =I21*I24 -> 133177.95 | J25: =J21*J24 -> 140630.46 | K25: =K21*K24 -> 148478.45 | ... AA25: =AA21*AA24 -> 348144.69 | AB25: =IFERROR(AA25*(1+((AA25/O25)^(1/12)-1))*(((1+((AA25/O25)^(1/12)-1))^12-1)/((AA25/O25)^(1/12)-1)),AA25*12) -> 5996321.2
B27: 5. Enterprise Direct Sales
B28: Enterprise Deals per month | D28: =ASSUMPTIONS!C54 -> 3 | E28: =D28*(1+ASSUMPTIONS!$C$22) -> 3.1030982 | F28: =E28*(1+ASSUMPTIONS!$C$22) -> 3.2097396 | G28: =F28*(1+ASSUMPTIONS!$C$22) -> 3.3200458 | H28: =G28*(1+ASSUMPTIONS!$C$22) -> 3.4341427 | I28: =H28*(1+ASSUMPTIONS!$C$22) -> 3.5521608 | J28: =I28*(1+ASSUMPTIONS!$C$22) -> 3.6742346 | K28: =J28*(1+ASSUMPTIONS!$C$22) -> 3.8005037 | L28: =K28*(1+ASSUMPTIONS!$C$22) -> 3.9311121 | ... AA28: =Z28*(1+ASSUMPTIONS!$C$22) -> 6.525736
B29: Enterprise Unit Price ($) | D29: =ASSUMPTIONS!C39 -> 3000 | E29: =D29*(1+ASSUMPTIONS!$C$24) -> 3007.3988 | F29: =E29*(1+ASSUMPTIONS!$C$24) -> 3014.8159 | G29: =F29*(1+ASSUMPTIONS!$C$24) -> 3022.2512 | H29: =G29*(1+ASSUMPTIONS!$C$24) -> 3029.7049 | I29: =H29*(1+ASSUMPTIONS!$C$24) -> 3037.177 | J29: =I29*(1+ASSUMPTIONS!$C$24) -> 3044.6675 | K29: =J29*(1+ASSUMPTIONS!$C$24) -> 3052.1764 | L29: =K29*(1+ASSUMPTIONS!$C$24) -> 3059.7039 | ... AA29: =Z29*(1+ASSUMPTIONS!$C$24) -> 3174.8699
B30: Enterprise Revenue ($) | D30: =D28*D29 -> 9000 | E30: =E28*E29 -> 9332.254 | F30: =F28*F29 -> 9676.7738 | G30: =G28*G29 -> 10034.012 | H30: =H28*H29 -> 10404.439 | I30: =I28*I29 -> 10788.541 | J30: =J28*J29 -> 11186.823 | K30: =K28*K29 -> 11599.808 | ... AA30: =AA28*AA29 -> 20718.363 | AB30: =IFERROR(AA30*(1+((AA30/O30)^(1/12)-1))*(((1+((AA30/O30)^(1/12)-1))^12-1)/((AA30/O30)^(1/12)-1)),AA30*12) -> 317152.61
B32: 6. Consolidated Revenue & Units
B33: Total Units / Order (DTC + Enterprise) | D33: =D21+D28 -> 95 | E33: =E21+E28 -> 100.08955 | F33: =F21+F28 -> 105.4356 | G33: =G21+G28 -> 111.05067 | H33: =H21+H28 -> 116.9479 | I33: =I21+I28 -> 123.14104 | J33: =J21+J28 -> 129.64452 | K33: =K21+K28 -> 136.47345 | ... AA33: =AA21+AA28 -> 305.58855 | AB33: =IFERROR(AA33*(1+((AA33/O33)^(1/12)-1))*(((1+((AA33/O33)^(1/12)-1))^12-1)/((AA33/O33)^(1/12)-1)),AA33*12) -> 5157.4198
B34: Total Revenue ($) | D34: =D25+D30 -> 110200 | E34: =E25+E30 -> 116280.47 | F34: =F25+F30 -> 122680.56 | G34: =G25+G30 -> 129416.65 | H34: =H25+H30 -> 136505.94 | I34: =I25+I30 -> 143966.49 | J34: =J25+J30 -> 151817.29 | K34: =K25+K30 -> 160078.26 | ... AA34: =AA25+AA30 -> 368863.05 | AB34: =IFERROR(AA34*(1+((AA34/O34)^(1/12)-1))*(((1+((AA34/O34)^(1/12)-1))^12-1)/((AA34/O34)^(1/12)-1)),AA34*12) -> 6306407.3

Sheet COST BUILD
A2: COST BUILD
D4: 2027 | P4: 2028
C5: Months | D5: 1 | E5: 2 | F5: 3 | G5: =F5+1 -> 4 | H5: =G5+1 -> 5 | I5: =H5+1 -> 6 | J5: =I5+1 -> 7 | K5: =J5+1 -> 8 | L5: =K5+1 -> 9 | M5: =L5+1 -> 10 | N5: =M5+1 -> 11 | ... AA5: =Z5+1 -> 24 | AB5: Year 3 (Annual)
B8: 1. Payroll (4 Consolidated Departments)
B9: R&D (Engineering + AI Research) | D9: =ASSUMPTIONS!C58 -> 55000 | E9: =D9*(1+ASSUMPTIONS!$C$26)+ASSUMPTIONS!$C$62*ASSUMPTIONS!$F$16 -> 56938.578 | F9: =E9*(1+ASSUMPTIONS!$C$26)+ASSUMPTIONS!$C$62*ASSUMPTIONS!$F$16 -> 58892.614 | G9: =F9*(1+ASSUMPTIONS!$C$26)+ASSUMPTIONS!$C$62*ASSUMPTIONS!$F$16 -> 60862.232 | H9: =G9*(1+ASSUMPTIONS!$C$26)+ASSUMPTIONS!$C$62*ASSUMPTIONS!$F$16 -> 62847.556 | I9: =H9*(1+ASSUMPTIONS!$C$26)+ASSUMPTIONS!$C$62*ASSUMPTIONS!$F$16 -> 64848.711 | J9: =I9*(1+ASSUMPTIONS!$C$26)+ASSUMPTIONS!$C$62*ASSUMPTIONS!$F$16 -> 66865.824 | K9: =J9*(1+ASSUMPTIONS!$C$26)+ASSUMPTIONS!$C$62*ASSUMPTIONS!$F$16 -> 68899.021 | L9: =K9*(1+ASSUMPTIONS!$C$26)+ASSUMPTIONS!$C$62*ASSUMPTIONS!$F$16 -> 70948.432 | ... AA9: =Z9*(1+ASSUMPTIONS!$C$26)+ASSUMPTIONS!$C$62*ASSUMPTIONS!$F$16 -> 103725.57
B10: Operations | D10: =ASSUMPTIONS!C59 -> 15000 | E10: =D10*(1+ASSUMPTIONS!$C$26)+ASSUMPTIONS!$F$16*ASSUMPTIONS!$C$62 -> 16619.612 | F10: =E10*(1+ASSUMPTIONS!$C$26)+ASSUMPTIONS!$F$16*ASSUMPTIONS!$C$62 -> 18252.139 | G10: =F10*(1+ASSUMPTIONS!$C$26)+ASSUMPTIONS!$F$16*ASSUMPTIONS!$C$62 -> 19897.684 | H10: =G10*(1+ASSUMPTIONS!$C$26)+ASSUMPTIONS!$F$16*ASSUMPTIONS!$C$62 -> 21556.351 | I10: =H10*(1+ASSUMPTIONS!$C$26)+ASSUMPTIONS!$F$16*ASSUMPTIONS!$C$62 -> 23228.245 | J10: =I10*(1+ASSUMPTIONS!$C$26)+ASSUMPTIONS!$F$16*ASSUMPTIONS!$C$62 -> 24913.47 | K10: =J10*(1+ASSUMPTIONS!$C$26)+ASSUMPTIONS!$F$16*ASSUMPTIONS!$C$62 -> 26612.133 | L10: =K10*(1+ASSUMPTIONS!$C$26)+ASSUMPTIONS!$F$16*ASSUMPTIONS!$C$62 -> 28324.342 | ... AA10: =Z10*(1+ASSUMPTIONS!$C$26)+ASSUMPTIONS!$F$16*ASSUMPTIONS!$C$62 -> 55708.463
B11: Growth (Marketing + Sales) | D11: =ASSUMPTIONS!C60 -> 12000 | E11: =D11*(1+ASSUMPTIONS!$C$26)+ASSUMPTIONS!$C$62*ASSUMPTIONS!$F$16 -> 13595.69 | F11: =E11*(1+ASSUMPTIONS!$C$26)+ASSUMPTIONS!$C$62*ASSUMPTIONS!$F$16 -> 15204.104 | G11: =F11*(1+ASSUMPTIONS!$C$26)+ASSUMPTIONS!$C$62*ASSUMPTIONS!$F$16 -> 16825.343 | H11: =G11*(1+ASSUMPTIONS!$C$26)+ASSUMPTIONS!$C$62*ASSUMPTIONS!$F$16 -> 18459.511 | I11: =H11*(1+ASSUMPTIONS!$C$26)+ASSUMPTIONS!$C$62*ASSUMPTIONS!$F$16 -> 20106.71 | J11: =I11*(1+ASSUMPTIONS!$C$26)+ASSUMPTIONS!$C$62*ASSUMPTIONS!$F$16 -> 21767.043 | K11: =J11*(1+ASSUMPTIONS!$C$26)+ASSUMPTIONS!$C$62*ASSUMPTIONS!$F$16 -> 23440.617 | L11: =K11*(1+ASSUMPTIONS!$C$26)+ASSUMPTIONS!$C$62*ASSUMPTIONS!$F$16 -> 25127.536 | ... AA11: =Z11*(1+ASSUMPTIONS!$C$26)+ASSUMPTIONS!$C$62*ASSUMPTIONS!$F$16 -> 52107.18
B12: Management | D12: =ASSUMPTIONS!C61 -> 10000 | E12: =D12*(1+ASSUMPTIONS!$C$26)+ASSUMPTIONS!$C$62*ASSUMPTIONS!$F$16 -> 11579.741 | F12: =E12*(1+ASSUMPTIONS!$C$26)+ASSUMPTIONS!$C$62*ASSUMPTIONS!$F$16 -> 13172.08 | G12: =F12*(1+ASSUMPTIONS!$C$26)+ASSUMPTIONS!$C$62*ASSUMPTIONS!$F$16 -> 14777.116 | H12: =G12*(1+ASSUMPTIONS!$C$26)+ASSUMPTIONS!$C$62*ASSUMPTIONS!$F$16 -> 16394.951 | I12: =H12*(1+ASSUMPTIONS!$C$26)+ASSUMPTIONS!$C$62*ASSUMPTIONS!$F$16 -> 18025.686 | J12: =I12*(1+ASSUMPTIONS!$C$26)+ASSUMPTIONS!$C$62*ASSUMPTIONS!$F$16 -> 19669.426 | K12: =J12*(1+ASSUMPTIONS!$C$26)+ASSUMPTIONS!$C$62*ASSUMPTIONS!$F$16 -> 21326.272 | L12: =K12*(1+ASSUMPTIONS!$C$26)+ASSUMPTIONS!$C$62*ASSUMPTIONS!$F$16 -> 22996.331 | ... AA12: =Z12*(1+ASSUMPTIONS!$C$26)+ASSUMPTIONS!$C$62*ASSUMPTIONS!$F$16 -> 49706.325
B13: Total Payroll | D13: =SUM(D9:D12) -> 92000 | E13: =SUM(E9:E12) -> 98733.621 | F13: =SUM(F9:F12) -> 105520.94 | G13: =SUM(G9:G12) -> 112362.38 | H13: =SUM(H9:H12) -> 119258.37 | I13: =SUM(I9:I12) -> 126209.35 | J13: =SUM(J9:J12) -> 133215.76 | K13: =SUM(K9:K12) -> 140278.04 | ... AA13: =SUM(AA9:AA12) -> 261247.54 | AB13: =IFERROR(AA13*(1+((AA13/O13)^(1/12)-1))*(((1+((AA13/O13)^(1/12)-1))^12-1)/((AA13/O13)^(1/12)-1)),AA13*12) -> 3999090.6
B15: 2. Operating Expenses (ex-payroll, ex-marketing - marketing lives in the P&L via the funnel)
B16: Software & Tools | D16: =ASSUMPTIONS!C63 -> 3500 | E16: =D16*(1+ASSUMPTIONS!$C$25) -> 3533.2108 | F16: =E16*(1+ASSUMPTIONS!$C$25) -> 3566.7367 | G16: =F16*(1+ASSUMPTIONS!$C$25) -> 3600.5807 | H16: =G16*(1+ASSUMPTIONS!$C$25) -> 3634.7459 | I16: =H16*(1+ASSUMPTIONS!$C$25) -> 3669.2352 | J16: =I16*(1+ASSUMPTIONS!$C$25) -> 3704.0518 | K16: =J16*(1+ASSUMPTIONS!$C$25) -> 3739.1988 | L16: =K16*(1+ASSUMPTIONS!$C$25) -> 3774.6793 | ... AA16: =Z16*(1+ASSUMPTIONS!$C$25) -> 4349.132
B17: Legal & Accounting | D17: =ASSUMPTIONS!C64 -> 6500 | E17: =D17*(1+ASSUMPTIONS!$C$25) -> 6561.6772 | F17: =E17*(1+ASSUMPTIONS!$C$25) -> 6623.9395 | G17: =F17*(1+ASSUMPTIONS!$C$25) -> 6686.7927 | H17: =G17*(1+ASSUMPTIONS!$C$25) -> 6750.2423 | I17: =H17*(1+ASSUMPTIONS!$C$25) -> 6814.294 | J17: =I17*(1+ASSUMPTIONS!$C$25) -> 6878.9534 | K17: =J17*(1+ASSUMPTIONS!$C$25) -> 6944.2264 | L17: =K17*(1+ASSUMPTIONS!$C$25) -> 7010.1187 | ... AA17: =Z17*(1+ASSUMPTIONS!$C$25) -> 8076.9594
B18: Rent & Facilities | D18: =ASSUMPTIONS!C65 -> 5500 | E18: =D18*(1+ASSUMPTIONS!$C$25) -> 5552.1884 | F18: =E18*(1+ASSUMPTIONS!$C$25) -> 5604.8719 | G18: =F18*(1+ASSUMPTIONS!$C$25) -> 5658.0554 | H18: =G18*(1+ASSUMPTIONS!$C$25) -> 5711.7435 | I18: =H18*(1+ASSUMPTIONS!$C$25) -> 5765.9411 | J18: =I18*(1+ASSUMPTIONS!$C$25) -> 5820.6529 | K18: =J18*(1+ASSUMPTIONS!$C$25) -> 5875.8839 | L18: =K18*(1+ASSUMPTIONS!$C$25) -> 5931.6389 | ... AA18: =Z18*(1+ASSUMPTIONS!$C$25) -> 6834.3503
B19: Other G&A Expenses | D19: =ASSUMPTIONS!C66 -> 2500 | E19: =D19*(1+ASSUMPTIONS!$C$25) -> 2523.722 | F19: =E19*(1+ASSUMPTIONS!$C$25) -> 2547.6691 | G19: =F19*(1+ASSUMPTIONS!$C$25) -> 2571.8434 | H19: =G19*(1+ASSUMPTIONS!$C$25) -> 2596.2471 | I19: =H19*(1+ASSUMPTIONS!$C$25) -> 2620.8823 | J19: =I19*(1+ASSUMPTIONS!$C$25) -> 2645.7513 | K19: =J19*(1+ASSUMPTIONS!$C$25) -> 2670.8563 | L19: =K19*(1+ASSUMPTIONS!$C$25) -> 2696.1995 | ... AA19: =Z19*(1+ASSUMPTIONS!$C$25) -> 3106.5228
B20: Total Opex (ex-payroll, ex-marketing) | D20: =SUM(D16:D19) -> 18000 | E20: =SUM(E16:E19) -> 18170.798 | F20: =SUM(F16:F19) -> 18343.217 | G20: =SUM(G16:G19) -> 18517.272 | H20: =SUM(H16:H19) -> 18692.979 | I20: =SUM(I16:I19) -> 18870.353 | J20: =SUM(J16:J19) -> 19049.409 | K20: =SUM(K16:K19) -> 19230.165 | ... AA20: =SUM(AA16:AA19) -> 22366.965 | AB20: =IFERROR(AA20*(1+((AA20/O20)^(1/12)-1))*(((1+((AA20/O20)^(1/12)-1))^12-1)/((AA20/O20)^(1/12)-1)),AA20*12) -> 285547.81
B22: 3. Capex & Depreciation (Simplified -
B23: Equipment & Tooling Capex | D23: =ASSUMPTIONS!C67 -> 12000 | E23: =D23*(1+ASSUMPTIONS!$C$25) -> 12113.866 | F23: =E23*(1+ASSUMPTIONS!$C$25) -> 12228.811 | G23: =F23*(1+ASSUMPTIONS!$C$25) -> 12344.848 | H23: =G23*(1+ASSUMPTIONS!$C$25) -> 12461.986 | I23: =H23*(1+ASSUMPTIONS!$C$25) -> 12580.235 | J23: =I23*(1+ASSUMPTIONS!$C$25) -> 12699.606 | K23: =J23*(1+ASSUMPTIONS!$C$25) -> 12820.11 | L23: =K23*(1+ASSUMPTIONS!$C$25) -> 12941.758 | ... AA23: =Z23*(1+ASSUMPTIONS!$C$25) -> 14911.31
B24: Office & Other Capex | D24: =ASSUMPTIONS!C68 -> 3000 | E24: =D24*(1+ASSUMPTIONS!$C$25) -> 3028.4664 | F24: =E24*(1+ASSUMPTIONS!$C$25) -> 3057.2029 | G24: =F24*(1+ASSUMPTIONS!$C$25) -> 3086.212 | H24: =G24*(1+ASSUMPTIONS!$C$25) -> 3115.4965 | I24: =H24*(1+ASSUMPTIONS!$C$25) -> 3145.0588 | J24: =I24*(1+ASSUMPTIONS!$C$25) -> 3174.9016 | K24: =J24*(1+ASSUMPTIONS!$C$25) -> 3205.0276 | L24: =K24*(1+ASSUMPTIONS!$C$25) -> 3235.4394 | ... AA24: =Z24*(1+ASSUMPTIONS!$C$25) -> 3727.8274
B25: Total Monthly Capex | D25: =SUM(D23:D24) -> 15000 | E25: =SUM(E23:E24) -> 15142.332 | F25: =SUM(F23:F24) -> 15286.014 | G25: =SUM(G23:G24) -> 15431.06 | H25: =SUM(H23:H24) -> 15577.482 | I25: =SUM(I23:I24) -> 15725.294 | J25: =SUM(J23:J24) -> 15874.508 | K25: =SUM(K23:K24) -> 16025.138 | ... AA25: =SUM(AA23:AA24) -> 18639.137 | AB25: =IFERROR(AA25*(1+((AA25/O25)^(1/12)-1))*(((1+((AA25/O25)^(1/12)-1))^12-1)/((AA25/O25)^(1/12)-1)),AA25*12) -> 237956.5
B26: Cumulative Capex | D26: =D25 -> 15000 | E26: =D26+E25 -> 30142.332 | F26: =E26+F25 -> 45428.346 | G26: =F26+G25 -> 60859.406 | H26: =G26+H25 -> 76436.889 | I26: =H26+I25 -> 92162.183 | J26: =I26+J25 -> 108036.69 | K26: =J26+K25 -> 124061.83 | L26: =K26+L25 -> 140239.03 | ... AB26: =AA26+AB25 -> 640115.14
B27: Monthly Depreciation | D27: =D26/ASSUMPTIONS!$C$69 -> 312.5 | E27: =E26/ASSUMPTIONS!$C$69 -> 627.96525 | F27: =F26/ASSUMPTIONS!$C$69 -> 946.42388 | G27: =G26/ASSUMPTIONS!$C$69 -> 1267.9043 | H27: =H26/ASSUMPTIONS!$C$69 -> 1592.4352 | I27: =I26/ASSUMPTIONS!$C$69 -> 1920.0455 | J27: =J26/ASSUMPTIONS!$C$69 -> 2250.7644 | K27: =K26/ASSUMPTIONS!$C$69 -> 2584.6214 | ... AA27: =AA26/ASSUMPTIONS!$C$69 -> 8378.3049 | AB27: =IFERROR(AA27*(1+((AA27/O27)^(1/12)-1))*(((1+((AA27/O27)^(1/12)-1))^12-1)/((AA27/O27)^(1/12)-1)),AA27*12) -> 154597.09
B28: Cumulative Depreciation | D28: =D27 -> 312.5 | E28: =D28+E27 -> 940.46525 | F28: =E28+F27 -> 1886.8891 | G28: =F28+G27 -> 3154.7934 | H28: =G28+H27 -> 4747.2286 | I28: =H28+I27 -> 6667.2741 | J28: =I28+J27 -> 8918.0385 | K28: =J28+K27 -> 11502.66 | L28: =K28+L27 -> 14424.306 | ... AB28: =AA28+AB27 -> 255537.73
B29: Net PP&E | D29: =D26-D28 -> 14687.5 | E29: =E26-E28 -> 29201.867 | F29: =F26-F28 -> 43541.457 | G29: =G26-G28 -> 57704.613 | H29: =H26-H28 -> 71689.66 | I29: =I26-I28 -> 85494.908 | J29: =J26-J28 -> 99118.652 | K29: =K26-K28 -> 112559.17 | ... AB29: =AB26-AB28 -> 384577.4

Sheet MONTHLY P&L
A2: MONTHLY P&L
D4: 2027 | P4: 2028
C5: Months | D5: 1 | E5: 2 | F5: 3 | G5: =F5+1 -> 4 | H5: =G5+1 -> 5 | I5: =H5+1 -> 6 | J5: =I5+1 -> 7 | K5: =J5+1 -> 8 | L5: =K5+1 -> 9 | M5: =L5+1 -> 10 | N5: =M5+1 -> 11 | ... AA5: =Z5+1 -> 24 | AB5: Year 3 (Annual)
B7: Revenue (DTC + Enterprise) | D7: ='CUSTOMER ACQUISITION & REVENUE'!D34 -> 110200 | E7: ='CUSTOMER ACQUISITION & REVENUE'!E34 -> 116280.47 | F7: ='CUSTOMER ACQUISITION & REVENUE'!F34 -> 122680.56 | G7: ='CUSTOMER ACQUISITION & REVENUE'!G34 -> 129416.65 | H7: ='CUSTOMER ACQUISITION & REVENUE'!H34 -> 136505.94 | I7: ='CUSTOMER ACQUISITION & REVENUE'!I34 -> 143966.49 | J7: ='CUSTOMER ACQUISITION & REVENUE'!J34 -> 151817.29 | K7: ='CUSTOMER ACQUISITION & REVENUE'!K34 -> 160078.26 | ... AB7: ='CUSTOMER ACQUISITION & REVENUE'!AB34 -> 6306407.3
B8: COGS | D8: =-('CUSTOMER ACQUISITION & REVENUE'!D21*ASSUMPTIONS!$C$40+ASSUMPTIONS!$C$41*'CUSTOMER ACQUISITION & REVENUE'!D28) -> -42746 | E8: =-('CUSTOMER ACQUISITION & REVENUE'!E21*ASSUMPTIONS!$C$40+ASSUMPTIONS!$C$41*'CUSTOMER ACQUISITION & REVENUE'!E28) -> -45005.14 | F8: =-('CUSTOMER ACQUISITION & REVENUE'!F21*ASSUMPTIONS!$C$40+ASSUMPTIONS!$C$41*'CUSTOMER ACQUISITION & REVENUE'!F28) -> -47377.246 | G8: =-('CUSTOMER ACQUISITION & REVENUE'!G21*ASSUMPTIONS!$C$40+ASSUMPTIONS!$C$41*'CUSTOMER ACQUISITION & REVENUE'!G28) -> -49867.807 | H8: =-('CUSTOMER ACQUISITION & REVENUE'!H21*ASSUMPTIONS!$C$40+ASSUMPTIONS!$C$41*'CUSTOMER ACQUISITION & REVENUE'!H28) -> -52482.576 | I8: =-('CUSTOMER ACQUISITION & REVENUE'!I21*ASSUMPTIONS!$C$40+ASSUMPTIONS!$C$41*'CUSTOMER ACQUISITION & REVENUE'!I28) -> -55227.582 | J8: =-('CUSTOMER ACQUISITION & REVENUE'!J21*ASSUMPTIONS!$C$40+ASSUMPTIONS!$C$41*'CUSTOMER ACQUISITION & REVENUE'!J28) -> -58109.141 | K8: =-('CUSTOMER ACQUISITION & REVENUE'!K21*ASSUMPTIONS!$C$40+ASSUMPTIONS!$C$41*'CUSTOMER ACQUISITION & REVENUE'!K28) -> -61133.873 | ... AA8: =-('CUSTOMER ACQUISITION & REVENUE'!AA21*ASSUMPTIONS!$C$40+ASSUMPTIONS!$C$41*'CUSTOMER ACQUISITION & REVENUE'!AA28) -> -135824.16 | AB8: =IFERROR(AA8*(1+((AA8/O8)^(1/12)-1))*(((1+((AA8/O8)^(1/12)-1))^12-1)/((AA8/O8)^(1/12)-1)),AA8*12) -> -2284747.5
B10: Gross Profit | D10: =SUM(D7:D8) -> 67454 | E10: =SUM(E7:E8) -> 71275.328 | F10: =SUM(F7:F8) -> 75303.317 | G10: =SUM(G7:G8) -> 79548.848 | H10: =SUM(H7:H8) -> 84023.366 | I10: =SUM(I7:I8) -> 88738.912 | J10: =SUM(J7:J8) -> 93708.146 | K10: =SUM(K7:K8) -> 98944.387 | ... AB10: =SUM(AB7:AB8) -> 4021659.9
B11: Gross Profit Margin | D11: =IFERROR(D10/D7,0) -> 0.61210526 | E11: =IFERROR(E10/E7,0) -> 0.61296045 | F11: =IFERROR(F10/F7,0) -> 0.6138162 | G11: =IFERROR(G10/G7,0) -> 0.61467242 | H11: =IFERROR(H10/H7,0) -> 0.615529 | I11: =IFERROR(I10/I7,0) -> 0.61638587 | J11: =IFERROR(J10/J7,0) -> 0.61724292 | K11: =IFERROR(K10/K7,0) -> 0.61810009 | ... AB11: =IFERROR(AB10/AB7,0) -> 0.63771013
B14: Variable Costs
B15: Marketing — Paid Traffic x CPC (customer acquisition cost) | D15: ='CUSTOMER ACQUISITION & REVENUE'!D9*ASSUMPTIONS!$C$52*ASSUMPTIONS!$F$15 -> 1050 | E15: ='CUSTOMER ACQUISITION & REVENUE'!E9*ASSUMPTIONS!$C$52*ASSUMPTIONS!$F$15 -> 1086.0844 | F15: ='CUSTOMER ACQUISITION & REVENUE'!F9*ASSUMPTIONS!$C$52*ASSUMPTIONS!$F$15 -> 1123.4089 | G15: ='CUSTOMER ACQUISITION & REVENUE'!G9*ASSUMPTIONS!$C$52*ASSUMPTIONS!$F$15 -> 1162.016 | H15: ='CUSTOMER ACQUISITION & REVENUE'!H9*ASSUMPTIONS!$C$52*ASSUMPTIONS!$F$15 -> 1201.95 | I15: ='CUSTOMER ACQUISITION & REVENUE'!I9*ASSUMPTIONS!$C$52*ASSUMPTIONS!$F$15 -> 1243.2563 | J15: ='CUSTOMER ACQUISITION & REVENUE'!J9*ASSUMPTIONS!$C$52*ASSUMPTIONS!$F$15 -> 1285.9821 | K15: ='CUSTOMER ACQUISITION & REVENUE'!K9*ASSUMPTIONS!$C$52*ASSUMPTIONS!$F$15 -> 1330.1763 | ... AA15: ='CUSTOMER ACQUISITION & REVENUE'!AA9*ASSUMPTIONS!$C$52*ASSUMPTIONS!$F$15 -> 2284.0076 | AB15: =IFERROR(AA15*(1+((AA15/O15)^(1/12)-1))*(((1+((AA15/O15)^(1/12)-1))^12-1)/((AA15/O15)^(1/12)-1)),AA15*12) -> 34372.553
B16: Organic Channel Investment | D16: =ASSUMPTIONS!$C$53*ASSUMPTIONS!$F$15 -> 2500 | E16: =ASSUMPTIONS!$C$53*ASSUMPTIONS!$F$15 -> 2500 | F16: =ASSUMPTIONS!$C$53*ASSUMPTIONS!$F$15 -> 2500 | G16: =ASSUMPTIONS!$C$53*ASSUMPTIONS!$F$15 -> 2500 | H16: =ASSUMPTIONS!$C$53*ASSUMPTIONS!$F$15 -> 2500 | I16: =ASSUMPTIONS!$C$53*ASSUMPTIONS!$F$15 -> 2500 | J16: =ASSUMPTIONS!$C$53*ASSUMPTIONS!$F$15 -> 2500 | K16: =ASSUMPTIONS!$C$53*ASSUMPTIONS!$F$15 -> 2500 | ... AA16: =ASSUMPTIONS!$C$53*ASSUMPTIONS!$F$15 -> 2500 | AB16: =IFERROR(AA16*(1+((AA16/O16)^(1/12)-1))*(((1+((AA16/O16)^(1/12)-1))^12-1)/((AA16/O16)^(1/12)-1)),AA16*12) -> 30000
B17: Fulfillment (Shipping x Orders) | D17: ='CUSTOMER ACQUISITION & REVENUE'!D21*ASSUMPTIONS!$C$42 -> 2300 | E17: ='CUSTOMER ACQUISITION & REVENUE'!E21*ASSUMPTIONS!$C$42 -> 2424.6614 | F17: ='CUSTOMER ACQUISITION & REVENUE'!F21*ASSUMPTIONS!$C$42 -> 2555.6466 | G17: ='CUSTOMER ACQUISITION & REVENUE'!G21*ASSUMPTIONS!$C$42 -> 2693.2657 | H17: ='CUSTOMER ACQUISITION & REVENUE'!H21*ASSUMPTIONS!$C$42 -> 2837.844 | I17: ='CUSTOMER ACQUISITION & REVENUE'!I21*ASSUMPTIONS!$C$42 -> 2989.722 | J17: ='CUSTOMER ACQUISITION & REVENUE'!J21*ASSUMPTIONS!$C$42 -> 3149.2571 | K17: ='CUSTOMER ACQUISITION & REVENUE'!K21*ASSUMPTIONS!$C$42 -> 3316.8236 | ... AA17: ='CUSTOMER ACQUISITION & REVENUE'!AA21*ASSUMPTIONS!$C$42 -> 7476.5703 | AB17: =IFERROR(AA17*(1+((AA17/O17)^(1/12)-1))*(((1+((AA17/O17)^(1/12)-1))^12-1)/((AA17/O17)^(1/12)-1)),AA17*12) -> 126537.13
B18: Total Variable Costs | D18: =SUM(D15:D17) -> 5850 | E18: =SUM(E15:E17) -> 6010.7458 | F18: =SUM(F15:F17) -> 6179.0554 | G18: =SUM(G15:G17) -> 6355.2817 | H18: =SUM(H15:H17) -> 6539.7939 | I18: =SUM(I15:I17) -> 6732.9783 | J18: =SUM(J15:J17) -> 6935.2393 | K18: =SUM(K15:K17) -> 7146.9999 | ... AB18: =SUM(AB15:AB17) -> 190909.68
B19: Contribution Margin | D19: =D10-D18 -> 61604 | E19: =E10-E18 -> 65264.583 | F19: =F10-F18 -> 69124.262 | G19: =G10-G18 -> 73193.566 | H19: =H10-H18 -> 77483.572 | I19: =I10-I18 -> 82005.933 | J19: =J10-J18 -> 86772.907 | K19: =K10-K18 -> 91797.387 | ... AB19: =AB10-AB18 -> 3830750.2
B20: Contribution Margin % | D20: =IFERROR(D19/D7,0) -> 0.55901996 | E20: =IFERROR(E19/E7,0) -> 0.56126866 | F20: =IFERROR(F19/F7,0) -> 0.56344917 | G20: =IFERROR(G19/G7,0) -> 0.56556528 | H20: =IFERROR(H19/H7,0) -> 0.56762051 | I20: =IFERROR(I19/I7,0) -> 0.56961819 | J20: =IFERROR(J19/J7,0) -> 0.57156144 | K20: =IFERROR(K19/K7,0) -> 0.57345318 | ... AB20: =IFERROR(AB19/AB7,0) -> 0.6074378
B22: Fixed Costs
B23: Payroll | D23: ='COST BUILD'!D13 -> 92000 | E23: ='COST BUILD'!E13 -> 98733.621 | F23: ='COST BUILD'!F13 -> 105520.94 | G23: ='COST BUILD'!G13 -> 112362.38 | H23: ='COST BUILD'!H13 -> 119258.37 | I23: ='COST BUILD'!I13 -> 126209.35 | J23: ='COST BUILD'!J13 -> 133215.76 | K23: ='COST BUILD'!K13 -> 140278.04 | ... AB23: ='COST BUILD'!AB13 -> 3999090.6
B24: Other Operating Expenses | D24: ='COST BUILD'!D20 -> 18000 | E24: ='COST BUILD'!E20 -> 18170.798 | F24: ='COST BUILD'!F20 -> 18343.217 | G24: ='COST BUILD'!G20 -> 18517.272 | H24: ='COST BUILD'!H20 -> 18692.979 | I24: ='COST BUILD'!I20 -> 18870.353 | J24: ='COST BUILD'!J20 -> 19049.409 | K24: ='COST BUILD'!K20 -> 19230.165 | ... AB24: ='COST BUILD'!AB20 -> 285547.81
B25: Total Fixed Costs | D25: =SUM(D23:D24) -> 110000 | E25: =SUM(E23:E24) -> 116904.42 | F25: =SUM(F23:F24) -> 123864.15 | G25: =SUM(G23:G24) -> 130879.65 | H25: =SUM(H23:H24) -> 137951.35 | I25: =SUM(I23:I24) -> 145079.7 | J25: =SUM(J23:J24) -> 152265.17 | K25: =SUM(K23:K24) -> 159508.21 | ... AB25: =SUM(AB23:AB24) -> 4284638.4
B27: EBITDA | D27: =D19-D25 -> -48396 | E27: =E19-E25 -> -51639.837 | F27: =F19-F25 -> -54739.892 | G27: =G19-G25 -> -57686.082 | H27: =H19-H25 -> -60467.775 | I27: =I19-I25 -> -63073.771 | J27: =J19-J25 -> -65492.266 | K27: =K19-K25 -> -67710.822 | ... AB27: =AB19-AB25 -> -453888.22
B28: EBITDA Margin % | D28: =IFERROR(D27/D7,0) -> -0.43916515 | E28: =IFERROR(E27/E7,0) -> -0.44409725 | F28: =IFERROR(F27/F7,0) -> -0.44619858 | G28: =IFERROR(G27/G7,0) -> -0.44573925 | H28: =IFERROR(H27/H7,0) -> -0.44296808 | I28: =IFERROR(I27/I7,0) -> -0.43811424 | J28: =IFERROR(J27/J7,0) -> -0.43138872 | K28: =IFERROR(K27/K7,0) -> -0.42298575 | ... AB28: =IFERROR(AB27/AB7,0) -> -0.07197255
B29: Depreciation & Amortization | D29: =-('COST BUILD'!D27) -> -312.5 | E29: =-('COST BUILD'!E27) -> -627.96525 | F29: =-('COST BUILD'!F27) -> -946.42388 | G29: =-('COST BUILD'!G27) -> -1267.9043 | H29: =-('COST BUILD'!H27) -> -1592.4352 | I29: =-('COST BUILD'!I27) -> -1920.0455 | J29: =-('COST BUILD'!J27) -> -2250.7644 | K29: =-('COST BUILD'!K27) -> -2584.6214 | ... AB29: =-('COST BUILD'!AB27) -> -154597.09
B30: EBT (Earnings Before Tax) | D30: =D27+D29 -> -48708.5 | E30: =E27+E29 -> -52267.802 | F30: =F27+F29 -> -55686.316 | G30: =G27+G29 -> -58953.986 | H30: =H27+H29 -> -62060.211 | I30: =I27+I29 -> -64993.817 | J30: =J27+J29 -> -67743.03 | K30: =K27+K29 -> -70295.444 | ... AB30: =AB27+AB29 -> -608485.31
B32: Tax | D32: =-MAX(D30,0)*ASSUMPTIONS!$C$76 -> 0 | E32: =-MAX(E30,0)*ASSUMPTIONS!$C$76 -> 0 | F32: =-MAX(F30,0)*ASSUMPTIONS!$C$76 -> 0 | G32: =-MAX(G30,0)*ASSUMPTIONS!$C$76 -> 0 | H32: =-MAX(H30,0)*ASSUMPTIONS!$C$76 -> 0 | I32: =-MAX(I30,0)*ASSUMPTIONS!$C$76 -> 0 | J32: =-MAX(J30,0)*ASSUMPTIONS!$C$76 -> 0 | K32: =-MAX(K30,0)*ASSUMPTIONS!$C$76 -> 0 | ... AB32: =-MAX(AB30,0)*ASSUMPTIONS!$C$76 -> 0
B33: Net Income | D33: =D30+D32 -> -48708.5 | E33: =E30+E32 -> -52267.802 | F33: =F30+F32 -> -55686.316 | G33: =G30+G32 -> -58953.986 | H33: =H30+H32 -> -62060.211 | I33: =I30+I32 -> -64993.817 | J33: =J30+J32 -> -67743.03 | K33: =K30+K32 -> -70295.444 | ... AB33: =AB30+AB32 -> -608485.31
B35: Annual Rollup Summary (Yr1 / Yr2 / Yr3)
C36: Year 1 | D36: Year 2 | E36: Year 3
B37: Revenue | C37: =SUM(D7:O7) -> 1802827.5 | D37: =SUM(P7:AA7) -> 3382590.9 | E37: =AB7 -> 6306407.3
B38: EBITDA | C38: =SUM(D27:O27) -> -757763.03 | D38: =SUM(P27:AA27) -> -873388.41 | E38: =AB27 -> -453888.22
B39: Net Income | C39: =SUM(D33:O33) -> -783006.56 | D39: =SUM(P33:AA33) -> -949085.52 | E39: =AB33 -> -608485.31

Sheet CFS & SOFP
A2: CASH FLOW STATEMENT & STATEMENT OF FINANCIAL POSITION
D4: 2027 | P4: 2028
C5: Months | D5: 1 | E5: 2 | F5: 3 | G5: =F5+1 -> 4 | H5: =G5+1 -> 5 | I5: =H5+1 -> 6 | J5: =I5+1 -> 7 | K5: =J5+1 -> 8 | L5: =K5+1 -> 9 | M5: =L5+1 -> 10 | N5: =M5+1 -> 11 | ... AA5: =Z5+1 -> 24 | AB5: Year 3 (Annual)
B8: Cash Flow Statement
B9: Net Income | D9: ='MONTHLY P&L'!D33 -> -48708.5 | E9: ='MONTHLY P&L'!E33 -> -52267.802 | F9: ='MONTHLY P&L'!F33 -> -55686.316 | G9: ='MONTHLY P&L'!G33 -> -58953.986 | H9: ='MONTHLY P&L'!H33 -> -62060.211 | I9: ='MONTHLY P&L'!I33 -> -64993.817 | J9: ='MONTHLY P&L'!J33 -> -67743.03 | K9: ='MONTHLY P&L'!K33 -> -70295.444 | ... AB9: ='MONTHLY P&L'!AB33 -> -608485.31
B10: + Depreciation | D10: =-('MONTHLY P&L'!D29) -> 312.5 | E10: =-('MONTHLY P&L'!E29) -> 627.96525 | F10: =-('MONTHLY P&L'!F29) -> 946.42388 | G10: =-('MONTHLY P&L'!G29) -> 1267.9043 | H10: =-('MONTHLY P&L'!H29) -> 1592.4352 | I10: =-('MONTHLY P&L'!I29) -> 1920.0455 | J10: =-('MONTHLY P&L'!J29) -> 2250.7644 | K10: =-('MONTHLY P&L'!K29) -> 2584.6214 | ... AB10: =-('MONTHLY P&L'!AB29) -> 154597.09
B11: (-) Increase in Accounts Receivable | D11: =-('MONTHLY P&L'!D7/30*ASSUMPTIONS!$C$73) -> -55100 | E11: =-(('MONTHLY P&L'!E7/30*ASSUMPTIONS!$C$73)-('MONTHLY P&L'!D7/30*ASSUMPTIONS!$C$73)) -> -3040.2344 | F11: =-(('MONTHLY P&L'!F7/30*ASSUMPTIONS!$C$73)-('MONTHLY P&L'!E7/30*ASSUMPTIONS!$C$73)) -> -3200.047 | G11: =-(('MONTHLY P&L'!G7/30*ASSUMPTIONS!$C$73)-('MONTHLY P&L'!F7/30*ASSUMPTIONS!$C$73)) -> -3368.0457 | H11: =-(('MONTHLY P&L'!H7/30*ASSUMPTIONS!$C$73)-('MONTHLY P&L'!G7/30*ASSUMPTIONS!$C$73)) -> -3544.6439 | I11: =-(('MONTHLY P&L'!I7/30*ASSUMPTIONS!$C$73)-('MONTHLY P&L'!H7/30*ASSUMPTIONS!$C$73)) -> -3730.2757 | J11: =-(('MONTHLY P&L'!J7/30*ASSUMPTIONS!$C$73)-('MONTHLY P&L'!I7/30*ASSUMPTIONS!$C$73)) -> -3925.397 | K11: =-(('MONTHLY P&L'!K7/30*ASSUMPTIONS!$C$73)-('MONTHLY P&L'!J7/30*ASSUMPTIONS!$C$73)) -> -4130.4865 | L11: =-(('MONTHLY P&L'!L7/30*ASSUMPTIONS!$C$73)-('MONTHLY P&L'!K7/30*ASSUMPTIONS!$C$73)) -> -4346.0468 | ... AA11: =-(('MONTHLY P&L'!AA7/30*ASSUMPTIONS!$C$73)-('MONTHLY P&L'!Z7/30*ASSUMPTIONS!$C$73)) -> -9266.7951 | AB11: =-(('MONTHLY P&L'!AB7/365*ASSUMPTIONS!$C$73)-('MONTHLY P&L'!AA7/30*ASSUMPTIONS!$C$73)) -> -74735.898
B12: (-) Increase in Inventory | D12: =-((-'MONTHLY P&L'!D8)/30*ASSUMPTIONS!$C$74) -> -64119 | E12: =-(((-'MONTHLY P&L'!E8)/30*ASSUMPTIONS!$C$74)-((-'MONTHLY P&L'!D8)/30*ASSUMPTIONS!$C$74)) -> -3388.7105 | F12: =-(((-'MONTHLY P&L'!F8)/30*ASSUMPTIONS!$C$74)-((-'MONTHLY P&L'!E8)/30*ASSUMPTIONS!$C$74)) -> -3558.1581 | G12: =-(((-'MONTHLY P&L'!G8)/30*ASSUMPTIONS!$C$74)-((-'MONTHLY P&L'!F8)/30*ASSUMPTIONS!$C$74)) -> -3735.8411 | H12: =-(((-'MONTHLY P&L'!H8)/30*ASSUMPTIONS!$C$74)-((-'MONTHLY P&L'!G8)/30*ASSUMPTIONS!$C$74)) -> -3922.1538 | I12: =-(((-'MONTHLY P&L'!I8)/30*ASSUMPTIONS!$C$74)-((-'MONTHLY P&L'!H8)/30*ASSUMPTIONS!$C$74)) -> -4117.509 | J12: =-(((-'MONTHLY P&L'!J8)/30*ASSUMPTIONS!$C$74)-((-'MONTHLY P&L'!I8)/30*ASSUMPTIONS!$C$74)) -> -4322.3394 | K12: =-(((-'MONTHLY P&L'!K8)/30*ASSUMPTIONS!$C$74)-((-'MONTHLY P&L'!J8)/30*ASSUMPTIONS!$C$74)) -> -4537.098 | L12: =-(((-'MONTHLY P&L'!L8)/30*ASSUMPTIONS!$C$74)-((-'MONTHLY P&L'!K8)/30*ASSUMPTIONS!$C$74)) -> -4762.2596 | ... AA12: =-(((-'MONTHLY P&L'!AA8)/30*ASSUMPTIONS!$C$74)-((-'MONTHLY P&L'!Z8)/30*ASSUMPTIONS!$C$74)) -> -9789.8459 | AB12: =-(((-'MONTHLY P&L'!AB8)/365*ASSUMPTIONS!$C$74)-((-'MONTHLY P&L'!AA8)/30*ASSUMPTIONS!$C$74)) -> -77944.955
B13: (+) Increase in Accounts Payable | D13: =(-'MONTHLY P&L'!D8)/30*ASSUMPTIONS!$C$75 -> 42746 | E13: =((-'MONTHLY P&L'!E8)/30*ASSUMPTIONS!$C$75)-((-'MONTHLY P&L'!D8)/30*ASSUMPTIONS!$C$75) -> 2259.1403 | F13: =((-'MONTHLY P&L'!F8)/30*ASSUMPTIONS!$C$75)-((-'MONTHLY P&L'!E8)/30*ASSUMPTIONS!$C$75) -> 2372.1054 | G13: =((-'MONTHLY P&L'!G8)/30*ASSUMPTIONS!$C$75)-((-'MONTHLY P&L'!F8)/30*ASSUMPTIONS!$C$75) -> 2490.5608 | H13: =((-'MONTHLY P&L'!H8)/30*ASSUMPTIONS!$C$75)-((-'MONTHLY P&L'!G8)/30*ASSUMPTIONS!$C$75) -> 2614.7692 | I13: =((-'MONTHLY P&L'!I8)/30*ASSUMPTIONS!$C$75)-((-'MONTHLY P&L'!H8)/30*ASSUMPTIONS!$C$75) -> 2745.006 | J13: =((-'MONTHLY P&L'!J8)/30*ASSUMPTIONS!$C$75)-((-'MONTHLY P&L'!I8)/30*ASSUMPTIONS!$C$75) -> 2881.5596 | K13: =((-'MONTHLY P&L'!K8)/30*ASSUMPTIONS!$C$75)-((-'MONTHLY P&L'!J8)/30*ASSUMPTIONS!$C$75) -> 3024.732 | L13: =((-'MONTHLY P&L'!L8)/30*ASSUMPTIONS!$C$75)-((-'MONTHLY P&L'!K8)/30*ASSUMPTIONS!$C$75) -> 3174.8398 | ... AA13: =((-'MONTHLY P&L'!AA8)/30*ASSUMPTIONS!$C$75)-((-'MONTHLY P&L'!Z8)/30*ASSUMPTIONS!$C$75) -> 6526.564 | AB13: =((-'MONTHLY P&L'!AB8)/365*ASSUMPTIONS!$C$75)-((-'MONTHLY P&L'!AA8)/30*ASSUMPTIONS!$C$75) -> 51963.303
B14: Cash Flow from Operations | D14: =SUM(D9:D13) -> -124869 | E14: =SUM(E9:E13) -> -55809.641 | F14: =SUM(F9:F13) -> -59125.992 | G14: =SUM(G9:G13) -> -62299.408 | H14: =SUM(H9:H13) -> -65319.804 | I14: =SUM(I9:I13) -> -68176.55 | J14: =SUM(J9:J13) -> -70858.442 | K14: =SUM(K9:K13) -> -73353.675 | ... AB14: =SUM(AB9:AB13) -> -554605.76
B16: Capital Expenditures | D16: =-('COST BUILD'!D25) -> -15000 | E16: =-('COST BUILD'!E25) -> -15142.332 | F16: =-('COST BUILD'!F25) -> -15286.014 | G16: =-('COST BUILD'!G25) -> -15431.06 | H16: =-('COST BUILD'!H25) -> -15577.482 | I16: =-('COST BUILD'!I25) -> -15725.294 | J16: =-('COST BUILD'!J25) -> -15874.508 | K16: =-('COST BUILD'!K25) -> -16025.138 | ... AB16: =-('COST BUILD'!AB25) -> -237956.5
B17: Cash Flow from Investing | D17: =D16 -> -15000 | E17: =E16 -> -15142.332 | F17: =F16 -> -15286.014 | G17: =G16 -> -15431.06 | H17: =H16 -> -15577.482 | I17: =I16 -> -15725.294 | J17: =J16 -> -15874.508 | K17: =K16 -> -16025.138 | ... AB17: =AB16 -> -237956.5
B19: Seed Equity Raised | D19: =ASSUMPTIONS!C30 -> 2000000 | E19: 0 | F19: 0 | G19: 0 | H19: 0 | I19: 0 | J19: 0 | K19: 0 | L19: 0 | M19: 0 | N19: 0 | O19: 0 | P19: 0 | Q19: 0 | R19: 0 | S19: 0 | T19: 0 | U19: 0 | V19: 0 | W19: 0 | X19: 0 | Y19: 0 | Z19: 0 | AA19: 0 | AB19: 0
B20: Cash Flow from Financing | D20: =D19 -> 2000000 | E20: =E19 -> 0 | F20: =F19 -> 0 | G20: =G19 -> 0 | H20: =H19 -> 0 | I20: =I19 -> 0 | J20: =J19 -> 0 | K20: =K19 -> 0 | ... AB20: =AB19 -> 0
B22: Net Change in Cash | D22: =D14+D17+D20 -> 1860131 | E22: =E14+E17+E20 -> -70951.973 | F22: =F14+F17+F20 -> -74412.006 | G22: =G14+G17+G20 -> -77730.468 | H22: =H14+H17+H20 -> -80897.286 | I22: =I14+I17+I20 -> -83901.844 | J22: =J14+J17+J20 -> -86732.95 | K22: =K14+K17+K20 -> -89378.813 | ... AB22: =AB14+AB17+AB20 -> -792562.27
B23: Beginning Cash Balance | D23: =C24 -> 0 | E23: =D24 -> 1860131 | F23: =E24 -> 1789179 | G23: =F24 -> 1714767 | H23: =G24 -> 1637036.6 | I23: =H24 -> 1556139.3 | J23: =I24 -> 1472237.4 | K23: =J24 -> 1385504.5 | ... AB23: =AA24 -> -285653.68
B24: Ending Cash Balance | D24: =SUM(D22:D23) -> 1860131 | E24: =SUM(E22:E23) -> 1789179 | F24: =SUM(F22:F23) -> 1714767 | G24: =SUM(G22:G23) -> 1637036.6 | H24: =SUM(H22:H23) -> 1556139.3 | I24: =SUM(I22:I23) -> 1472237.4 | J24: =SUM(J22:J23) -> 1385504.5 | K24: =SUM(K22:K23) -> 1296125.7 | ... AB24: =SUM(AB22:AB23) -> -1078215.9
B26: Statement of Financial Position
B27: Assets
B28: Cash | D28: =D24 -> 1860131 | E28: =E24 -> 1789179 | F28: =F24 -> 1714767 | G28: =G24 -> 1637036.6 | H28: =H24 -> 1556139.3 | I28: =I24 -> 1472237.4 | J28: =J24 -> 1385504.5 | K28: =K24 -> 1296125.7 | ... AB28: =AB24 -> -1078215.9
B29: Accounts Receivable | D29: =('MONTHLY P&L'!D7/30*ASSUMPTIONS!$C$73) -> 55100 | E29: =('MONTHLY P&L'!E7/30*ASSUMPTIONS!$C$73) -> 58140.234 | F29: =('MONTHLY P&L'!F7/30*ASSUMPTIONS!$C$73) -> 61340.281 | G29: =('MONTHLY P&L'!G7/30*ASSUMPTIONS!$C$73) -> 64708.327 | H29: =('MONTHLY P&L'!H7/30*ASSUMPTIONS!$C$73) -> 68252.971 | I29: =('MONTHLY P&L'!I7/30*ASSUMPTIONS!$C$73) -> 71983.247 | J29: =('MONTHLY P&L'!J7/30*ASSUMPTIONS!$C$73) -> 75908.644 | K29: =('MONTHLY P&L'!K7/30*ASSUMPTIONS!$C$73) -> 80039.13 | ... AA29: =('MONTHLY P&L'!AA7/30*ASSUMPTIONS!$C$73) -> 184431.53 | AB29: =('MONTHLY P&L'!AB7/365*ASSUMPTIONS!$C$73) -> 259167.43
B30: Inventory | D30: =((-'MONTHLY P&L'!D8)/30*ASSUMPTIONS!$C$74) -> 64119 | E30: =((-'MONTHLY P&L'!E8)/30*ASSUMPTIONS!$C$74) -> 67507.711 | F30: =((-'MONTHLY P&L'!F8)/30*ASSUMPTIONS!$C$74) -> 71065.869 | G30: =((-'MONTHLY P&L'!G8)/30*ASSUMPTIONS!$C$74) -> 74801.71 | H30: =((-'MONTHLY P&L'!H8)/30*ASSUMPTIONS!$C$74) -> 78723.864 | I30: =((-'MONTHLY P&L'!I8)/30*ASSUMPTIONS!$C$74) -> 82841.373 | J30: =((-'MONTHLY P&L'!J8)/30*ASSUMPTIONS!$C$74) -> 87163.712 | K30: =((-'MONTHLY P&L'!K8)/30*ASSUMPTIONS!$C$74) -> 91700.81 | ... AA30: =((-'MONTHLY P&L'!AA8)/30*ASSUMPTIONS!$C$74) -> 203736.24 | AB30: =((-'MONTHLY P&L'!AB8)/365*ASSUMPTIONS!$C$74) -> 281681.2
B31: Total Current Assets | D31: =SUM(D28:D30) -> 1979350 | E31: =SUM(E28:E30) -> 1914827 | F31: =SUM(F28:F30) -> 1847173.2 | G31: =SUM(G28:G30) -> 1776546.6 | H31: =SUM(H28:H30) -> 1703116.1 | I31: =SUM(I28:I30) -> 1627062 | J31: =SUM(J28:J30) -> 1548576.8 | K31: =SUM(K28:K30) -> 1467865.6 | ... AB31: =SUM(AB28:AB30) -> -537367.32
B32: Net PP&E | D32: ='COST BUILD'!D29 -> 14687.5 | E32: ='COST BUILD'!E29 -> 29201.867 | F32: ='COST BUILD'!F29 -> 43541.457 | G32: ='COST BUILD'!G29 -> 57704.613 | H32: ='COST BUILD'!H29 -> 71689.66 | I32: ='COST BUILD'!I29 -> 85494.908 | J32: ='COST BUILD'!J29 -> 99118.652 | K32: ='COST BUILD'!K29 -> 112559.17 | ... AB32: ='COST BUILD'!AB29 -> 384577.4
B33: Total Assets | D33: =SUM(D31:D32) -> 1994037.5 | E33: =SUM(E31:E32) -> 1944028.8 | F33: =SUM(F31:F32) -> 1890714.6 | G33: =SUM(G31:G32) -> 1834251.2 | H33: =SUM(H31:H32) -> 1774805.8 | I33: =SUM(I31:I32) -> 1712557 | J33: =SUM(J31:J32) -> 1647695.5 | K33: =SUM(K31:K32) -> 1580424.8 | ... AB33: =SUM(AB31:AB32) -> -152789.92
B35: Liabilities
B36: Accounts Payable | D36: =(-'MONTHLY P&L'!D8)/30*ASSUMPTIONS!$C$75 -> 42746 | E36: =(-'MONTHLY P&L'!E8)/30*ASSUMPTIONS!$C$75 -> 45005.14 | F36: =(-'MONTHLY P&L'!F8)/30*ASSUMPTIONS!$C$75 -> 47377.246 | G36: =(-'MONTHLY P&L'!G8)/30*ASSUMPTIONS!$C$75 -> 49867.807 | H36: =(-'MONTHLY P&L'!H8)/30*ASSUMPTIONS!$C$75 -> 52482.576 | I36: =(-'MONTHLY P&L'!I8)/30*ASSUMPTIONS!$C$75 -> 55227.582 | J36: =(-'MONTHLY P&L'!J8)/30*ASSUMPTIONS!$C$75 -> 58109.141 | K36: =(-'MONTHLY P&L'!K8)/30*ASSUMPTIONS!$C$75 -> 61133.873 | ... AA36: =(-'MONTHLY P&L'!AA8)/30*ASSUMPTIONS!$C$75 -> 135824.16 | AB36: =(-'MONTHLY P&L'!AB8)/365*ASSUMPTIONS!$C$75 -> 187787.46
B37: Total Liabilities | D37: =D36 -> 42746 | E37: =E36 -> 45005.14 | F37: =F36 -> 47377.246 | G37: =G36 -> 49867.807 | H37: =H36 -> 52482.576 | I37: =I36 -> 55227.582 | J37: =J36 -> 58109.141 | K37: =K36 -> 61133.873 | ... AB37: =AB36 -> 187787.46
B39: Equity
B40: Paid-In Capital | D40: =ASSUMPTIONS!C30 -> 2000000 | E40: =D40 -> 2000000 | F40: =E40 -> 2000000 | G40: =F40 -> 2000000 | H40: =G40 -> 2000000 | I40: =H40 -> 2000000 | J40: =I40 -> 2000000 | K40: =J40 -> 2000000 | L40: =K40 -> 2000000 | ... AB40: =AA40 -> 2000000
B41: Retained Earnings (cumulative Net Income) | D41: ='MONTHLY P&L'!D33 -> -48708.5 | E41: =D41+'MONTHLY P&L'!E33 -> -100976.3 | F41: =E41+'MONTHLY P&L'!F33 -> -156662.62 | G41: =F41+'MONTHLY P&L'!G33 -> -215616.6 | H41: =G41+'MONTHLY P&L'!H33 -> -277676.81 | I41: =H41+'MONTHLY P&L'!I33 -> -342670.63 | J41: =I41+'MONTHLY P&L'!J33 -> -410413.66 | K41: =J41+'MONTHLY P&L'!K33 -> -480709.1 | L41: =K41+'MONTHLY P&L'!L33 -> -553347.09 | ... AB41: =AA41+'MONTHLY P&L'!AB33 -> -2340577.4
B42: Total Equity | D42: =SUM(D40:D41) -> 1951291.5 | E42: =SUM(E40:E41) -> 1899023.7 | F42: =SUM(F40:F41) -> 1843337.4 | G42: =SUM(G40:G41) -> 1784383.4 | H42: =SUM(H40:H41) -> 1722323.2 | I42: =SUM(I40:I41) -> 1657329.4 | J42: =SUM(J40:J41) -> 1589586.3 | K42: =SUM(K40:K41) -> 1519290.9 | ... AB42: =SUM(AB40:AB41) -> -340577.38
B44: Total Liabilities + Equity | D44: =D42+D37 -> 1994037.5 | E44: =E42+E37 -> 1944028.8 | F44: =F42+F37 -> 1890714.6 | G44: =G42+G37 -> 1834251.2 | H44: =H42+H37 -> 1774805.8 | I44: =I42+I37 -> 1712557 | J44: =J42+J37 -> 1647695.5 | K44: =K42+K37 -> 1580424.8 | ... AB44: =AB42+AB37 -> -152789.92
D45: =D44=D33 -> TRUE | E45: =E44=E33 -> TRUE | F45: =F44=F33 -> TRUE | G45: =G44=G33 -> TRUE | H45: =H44=H33 -> TRUE | I45: =I44=I33 -> TRUE | J45: =J44=J33 -> TRUE | K45: =K44=K33 -> TRUE | ... AB45: =AB44=AB33 -> TRUE

Sheet RUNWAY BURN & BREAKEVEN
A2: RUNWAY BURN AND BREAK EVEN ANALYSIS
D4: 2027 | P4: 2028
C5: Months | D5: 1 | E5: 2 | F5: 3 | G5: =F5+1 -> 4 | H5: =G5+1 -> 5 | I5: =H5+1 -> 6 | J5: =I5+1 -> 7 | K5: =J5+1 -> 8 | L5: =K5+1 -> 9 | M5: =L5+1 -> 10 | N5: =M5+1 -> 11 | ... AA5: =Z5+1 -> 24 | AB5: Year 3 (Annual)
B8: Runway & Burn
B9: Cash Balance (End of Period) | D9: ='CFS & SOFP'!D24 -> 1860131 | E9: ='CFS & SOFP'!E24 -> 1789179 | F9: ='CFS & SOFP'!F24 -> 1714767 | G9: ='CFS & SOFP'!G24 -> 1637036.6 | H9: ='CFS & SOFP'!H24 -> 1556139.3 | I9: ='CFS & SOFP'!I24 -> 1472237.4 | J9: ='CFS & SOFP'!J24 -> 1385504.5 | K9: ='CFS & SOFP'!K24 -> 1296125.7 | ... AB9: ='CFS & SOFP'!AB24 -> -1078215.9
B10: Gross Burn (Revenue - EBITDA = total cash costs) | D10: ='MONTHLY P&L'!D7-'MONTHLY P&L'!D27 -> 158596 | E10: ='MONTHLY P&L'!E7-'MONTHLY P&L'!E27 -> 167920.31 | F10: ='MONTHLY P&L'!F7-'MONTHLY P&L'!F27 -> 177420.46 | G10: ='MONTHLY P&L'!G7-'MONTHLY P&L'!G27 -> 187102.74 | H10: ='MONTHLY P&L'!H7-'MONTHLY P&L'!H27 -> 196973.72 | I10: ='MONTHLY P&L'!I7-'MONTHLY P&L'!I27 -> 207040.26 | J10: ='MONTHLY P&L'!J7-'MONTHLY P&L'!J27 -> 217309.55 | K10: ='MONTHLY P&L'!K7-'MONTHLY P&L'!K27 -> 227789.08 | ... AB10: ='MONTHLY P&L'!AB7-'MONTHLY P&L'!AB27 -> 6760295.6
B11: Net Burn (= -EBITDA; positive = burning cash) | D11: =-'MONTHLY P&L'!D27 -> 48396 | E11: =-'MONTHLY P&L'!E27 -> 51639.837 | F11: =-'MONTHLY P&L'!F27 -> 54739.892 | G11: =-'MONTHLY P&L'!G27 -> 57686.082 | H11: =-'MONTHLY P&L'!H27 -> 60467.775 | I11: =-'MONTHLY P&L'!I27 -> 63073.771 | J11: =-'MONTHLY P&L'!J27 -> 65492.266 | K11: =-'MONTHLY P&L'!K27 -> 67710.822 | ... AB11: =-'MONTHLY P&L'!AB27 -> 453888.22
B13: Runway Remaining (Months) | D13: =IF(D11<=0,"Cash-flow positive",D9/D11) -> 38.435635 | E13: =IF(E11<=0,"Cash-flow positive",E9/E11) -> 34.647264 | F13: =IF(F11<=0,"Cash-flow positive",F9/F11) -> 31.325729 | G13: =IF(G11<=0,"Cash-flow positive",G9/G11) -> 28.378363 | H13: =IF(H11<=0,"Cash-flow positive",H9/H11) -> 25.735018 | I13: =IF(I11<=0,"Cash-flow positive",I9/I11) -> 23.341516 | J13: =IF(J11<=0,"Cash-flow positive",J9/J11) -> 21.155238 | K13: =IF(K11<=0,"Cash-flow positive",K9/K11) -> 19.142075 | ... AA13: =IF(AA11<=0,"Cash-flow positive",AA9/AA11) -> -4.546006 | AB13: =IF(AB11<=0,"Cash-flow positive",AB9/(AB11/12)) -> -28.506119
B15: No-Revenue Downside (Month-1 Fixed Costs Only)
B16: Month-1 Payroll + Opex (Fixed Cost Base) | C16: ='MONTHLY P&L'!D23+'MONTHLY P&L'!D24 -> 110000
B17: Implied Runway (Months) on $2.0M Raise, No Revenue | C17: =ASSUMPTIONS!C30/'RUNWAY BURN & BREAKEVEN'!C16 -> 18.181818
B19: Minimum Cash Threshold Alert ($) | C19: 150000
B20: Below Minimum Threshold? | D20: =IF(D9<$C$19,"⚠ FUNDING NEEDED","OK") -> OK | E20: =IF(E9<$C$19,"⚠ FUNDING NEEDED","OK") -> OK | F20: =IF(F9<$C$19,"⚠ FUNDING NEEDED","OK") -> OK | G20: =IF(G9<$C$19,"⚠ FUNDING NEEDED","OK") -> OK | H20: =IF(H9<$C$19,"⚠ FUNDING NEEDED","OK") -> OK | I20: =IF(I9<$C$19,"⚠ FUNDING NEEDED","OK") -> OK | J20: =IF(J9<$C$19,"⚠ FUNDING NEEDED","OK") -> OK | K20: =IF(K9<$C$19,"⚠ FUNDING NEEDED","OK") -> OK | ... AB20: =IF(AB9<$C$19,"⚠ FUNDING NEEDED","OK") -> ⚠ FUNDING NEEDED
B23: Break-Even Analysis
B24: Blended ASP ($/unit) | D24: =IFERROR('MONTHLY P&L'!D7/'CUSTOMER ACQUISITION & REVENUE'!D33,0) -> 1160 | E24: =IFERROR('MONTHLY P&L'!E7/'CUSTOMER ACQUISITION & REVENUE'!E33,0) -> 1161.7643 | F24: =IFERROR('MONTHLY P&L'!F7/'CUSTOMER ACQUISITION & REVENUE'!F33,0) -> 1163.5592 | G24: =IFERROR('MONTHLY P&L'!G7/'CUSTOMER ACQUISITION & REVENUE'!G33,0) -> 1165.3838 | H24: =IFERROR('MONTHLY P&L'!H7/'CUSTOMER ACQUISITION & REVENUE'!H33,0) -> 1167.2372 | I24: =IFERROR('MONTHLY P&L'!I7/'CUSTOMER ACQUISITION & REVENUE'!I33,0) -> 1169.1187 | J24: =IFERROR('MONTHLY P&L'!J7/'CUSTOMER ACQUISITION & REVENUE'!J33,0) -> 1171.0274 | K24: =IFERROR('MONTHLY P&L'!K7/'CUSTOMER ACQUISITION & REVENUE'!K33,0) -> 1172.9627 | ... AB24: =IFERROR('MONTHLY P&L'!AB7/'CUSTOMER ACQUISITION & REVENUE'!AB33,0) -> 1222.7834
B25: Blended Variable Cost ($/unit) | D25: =IFERROR((-'MONTHLY P&L'!D8+'MONTHLY P&L'!D18)/'CUSTOMER ACQUISITION & REVENUE'!D33,0) -> 511.53684 | E25: =IFERROR((-'MONTHLY P&L'!E8+'MONTHLY P&L'!E18)/'CUSTOMER ACQUISITION & REVENUE'!E33,0) -> 509.70241 | F25: =IFERROR((-'MONTHLY P&L'!F8+'MONTHLY P&L'!F18)/'CUSTOMER ACQUISITION & REVENUE'!F33,0) -> 507.95272 | G25: =IFERROR((-'MONTHLY P&L'!G8+'MONTHLY P&L'!G18)/'CUSTOMER ACQUISITION & REVENUE'!G33,0) -> 506.28318 | H25: =IFERROR((-'MONTHLY P&L'!H8+'MONTHLY P&L'!H18)/'CUSTOMER ACQUISITION & REVENUE'!H33,0) -> 504.68943 | I25: =IFERROR((-'MONTHLY P&L'!I8+'MONTHLY P&L'!I18)/'CUSTOMER ACQUISITION & REVENUE'!I33,0) -> 503.16742 | J25: =IFERROR((-'MONTHLY P&L'!J8+'MONTHLY P&L'!J18)/'CUSTOMER ACQUISITION & REVENUE'!J33,0) -> 501.7133 | K25: =IFERROR((-'MONTHLY P&L'!K8+'MONTHLY P&L'!K18)/'CUSTOMER ACQUISITION & REVENUE'!K33,0) -> 500.3235 | ... AB25: =IFERROR((-'MONTHLY P&L'!AB8+'MONTHLY P&L'!AB18)/'CUSTOMER ACQUISITION & REVENUE'!AB33,0) -> 480.01855
B26: Contribution Margin ($/unit) | D26: =D24-D25 -> 648.46316 | E26: =E24-E25 -> 652.06188 | F26: =F24-F25 -> 655.60646 | G26: =G24-G25 -> 659.1006 | H26: =H24-H25 -> 662.54778 | I26: =I24-I25 -> 665.95127 | J26: =J24-J25 -> 669.31411 | K26: =K24-K25 -> 672.63917 | ... AB26: =AB24-AB25 -> 742.76485
B28: Fixed Costs (Payroll+Opex+D&A) | D28: ='MONTHLY P&L'!D23+'MONTHLY P&L'!D24-'MONTHLY P&L'!D29 -> 110312.5 | E28: ='MONTHLY P&L'!E23+'MONTHLY P&L'!E24-'MONTHLY P&L'!E29 -> 117532.38 | F28: ='MONTHLY P&L'!F23+'MONTHLY P&L'!F24-'MONTHLY P&L'!F29 -> 124810.58 | G28: ='MONTHLY P&L'!G23+'MONTHLY P&L'!G24-'MONTHLY P&L'!G29 -> 132147.55 | H28: ='MONTHLY P&L'!H23+'MONTHLY P&L'!H24-'MONTHLY P&L'!H29 -> 139543.78 | I28: ='MONTHLY P&L'!I23+'MONTHLY P&L'!I24-'MONTHLY P&L'!I29 -> 146999.75 | J28: ='MONTHLY P&L'!J23+'MONTHLY P&L'!J24-'MONTHLY P&L'!J29 -> 154515.94 | K28: ='MONTHLY P&L'!K23+'MONTHLY P&L'!K24-'MONTHLY P&L'!K29 -> 162092.83 | ... AB28: ='MONTHLY P&L'!AB23+'MONTHLY P&L'!AB24-'MONTHLY P&L'!AB29 -> 4439235.5
B29: Break-Even Units Needed | D29: =IF(D26<=0,"n/m",D28/D26) -> 170.11375 | E29: =IF(E26<=0,"n/m",E28/E26) -> 180.24729 | F29: =IF(F26<=0,"n/m",F28/F26) -> 190.37423 | G29: =IF(G26<=0,"n/m",G28/G26) -> 200.49679 | H29: =IF(H26<=0,"n/m",H28/H26) -> 210.61693 | I29: =IF(I26<=0,"n/m",I28/I26) -> 220.7365 | J29: =IF(J26<=0,"n/m",J28/J26) -> 230.85713 | K29: =IF(K26<=0,"n/m",K28/K26) -> 240.98036 | ... AB29: =IF(AB26<=0,"n/m",AB28/AB26) -> 5976.6364
B30: Actual Units Sold | D30: ='CUSTOMER ACQUISITION & REVENUE'!D33 -> 95 | E30: ='CUSTOMER ACQUISITION & REVENUE'!E33 -> 100.08955 | F30: ='CUSTOMER ACQUISITION & REVENUE'!F33 -> 105.4356 | G30: ='CUSTOMER ACQUISITION & REVENUE'!G33 -> 111.05067 | H30: ='CUSTOMER ACQUISITION & REVENUE'!H33 -> 116.9479 | I30: ='CUSTOMER ACQUISITION & REVENUE'!I33 -> 123.14104 | J30: ='CUSTOMER ACQUISITION & REVENUE'!J33 -> 129.64452 | K30: ='CUSTOMER ACQUISITION & REVENUE'!K33 -> 136.47345 | ... AB30: ='CUSTOMER ACQUISITION & REVENUE'!AB33 -> 5157.4198
B31: Break-Even Status | D31: =IF(ISNUMBER(D29),IF(D30>=D29,"✓ BREAK-EVEN","Below BE"),"n/m") -> Below BE | E31: =IF(ISNUMBER(E29),IF(E30>=E29,"✓ BREAK-EVEN","Below BE"),"n/m") -> Below BE | F31: =IF(ISNUMBER(F29),IF(F30>=F29,"✓ BREAK-EVEN","Below BE"),"n/m") -> Below BE | G31: =IF(ISNUMBER(G29),IF(G30>=G29,"✓ BREAK-EVEN","Below BE"),"n/m") -> Below BE | H31: =IF(ISNUMBER(H29),IF(H30>=H29,"✓ BREAK-EVEN","Below BE"),"n/m") -> Below BE | I31: =IF(ISNUMBER(I29),IF(I30>=I29,"✓ BREAK-EVEN","Below BE"),"n/m") -> Below BE | J31: =IF(ISNUMBER(J29),IF(J30>=J29,"✓ BREAK-EVEN","Below BE"),"n/m") -> Below BE | K31: =IF(ISNUMBER(K29),IF(K30>=K29,"✓ BREAK-EVEN","Below BE"),"n/m") -> Below BE | ... AB31: =IF(ISNUMBER(AB29),IF(AB30>=AB29,"✓ BREAK-EVEN","Below BE"),"n/m") -> Below BE

Sheet CAP TABLE & INVESTOR RETURNS
A2: CAP TABLE AND INVESTOR RETURNS
B4: SEED ROUND TERMS
B6: Seed Raise Amount ($) | D6: =ASSUMPTIONS!C30 -> 2000000
B7: Ownership Sold to Investors (%) | D7: =ASSUMPTIONS!C31 -> 0.15
B8: Post-Money Valuation ($) | D8: =ASSUMPTIONS!C32 -> 13333333
B9: Pre-Money Valuation ($) | D9: =ASSUMPTIONS!C33 -> 11333333
B10: Founder Ownership (%) | D10: =ASSUMPTIONS!C34 -> 0.85
B13: Investor Returns (Undiluted)
B15: Hold Period (Years) | C15: 3
B17: Exit Enterprise Value ($) | C17: Investor Proceeds ($) | D17: MOIC (x) | E17: IRR (%, implied CAGR)
B18: 25000000 | C18: =B18*$D$7 -> 3750000 | D18: =C18/ASSUMPTIONS!$C$30 -> 1.875 | E18: =(D18)^(1/$C$15)-1 -> 0.23310604
B19: 50000000 | C19: =B19*$D$7 -> 7500000 | D19: =C19/ASSUMPTIONS!$C$30 -> 3.75 | E19: =(D19)^(1/$C$15)-1 -> 0.55361625
B20: 100000000 | C20: =B20*$D$7 -> 15000000 | D20: =C20/ASSUMPTIONS!$C$30 -> 7.5 | E20: =(D20)^(1/$C$15)-1 -> 0.95743382
B21: 250000000 | C21: =B21*$D$7 -> 37500000 | D21: =C21/ASSUMPTIONS!$C$30 -> 18.75 | E21: =(D21)^(1/$C$15)-1 -> 1.6566464
B27: Exit Scenarios
B29: Exit Path | C29: Revenue Multiple | D29: Year-3 Revenue ($) | E29: Enterprise Value ($) | F29: Equity Value ($) | G29: Investor Proceeds ($)
B30: Strategic Acquisition | C30: =ASSUMPTIONS!C80 -> 8 | D30: ='MONTHLY P&L'!E37 -> 6306407.3 | E30: =C30*D30 -> 50451259 | F30: =E30+'CFS & SOFP'!$AB$28 -> 49373043 | G30: =F30*$D$7 -> 7405956.4
B31: Private Equity Exit | C31: =ASSUMPTIONS!C81 -> 6 | D31: ='MONTHLY P&L'!E37 -> 6306407.3 | E31: =C31*D31 -> 37838444 | F31: =E31+'CFS & SOFP'!$AB$28 -> 36760228 | G31: =F31*$D$7 -> 5514034.2
B32: IPO | C32: =ASSUMPTIONS!C82 -> 12 | D32: ='MONTHLY P&L'!E37 -> 6306407.3 | E32: =C32*D32 -> 75676888 | F32: =E32+'CFS & SOFP'!$AB$28 -> 74598672 | G32: =F32*$D$7 -> 11189801

Sheet DASHBOARD
A2: EXECUTIVE DASHBOARD
C4: =ASSUMPTIONS!C6 -> Base
C6: KEY METRICS
C7: Revenue (Month 24) | F7: ='MONTHLY P&L'!AA7 -> 368863.05 | I7: Revenue (Year 3, annualized) | M7: ='MONTHLY P&L'!AB7 -> 6306407.3 | O7: EBITDA Margin (Month 24) | S7: ='MONTHLY P&L'!AA28 -> -0.17035099
C9: Gross Margin (Month 24) | F9: ='MONTHLY P&L'!AA11 -> 0.63177618 | I9: Cash Balance (Month 24) | M9: ='CFS & SOFP'!AA24 -> -285653.68 | O9: Runway (Month 1, months) | S9: ='RUNWAY BURN & BREAKEVEN'!D13 -> 38.435635
C11: Break-Even Status (Month 24) | F11: ='RUNWAY BURN & BREAKEVEN'!AA31 -> Below BE | I11: MOIC @ $100M Exit | M11: ='CAP TABLE & INVESTOR RETURNS'!D20 -> 7.5 | O11: IRR @ $100M Exit | S11: ='CAP TABLE & INVESTOR RETURNS'!E20 -> 0.95743382
B16: CHARTS
C17: Chart Source (Month #) | E17: 1 | F17: =E17+1 -> 2 | G17: =F17+1 -> 3 | H17: =G17+1 -> 4 | I17: =H17+1 -> 5 | J17: =I17+1 -> 6 | K17: =J17+1 -> 7 | L17: =K17+1 -> 8 | M17: =L17+1 -> 9 | ... AB17: =AA17+1 -> 24
C19: Revenue | E19: ='MONTHLY P&L'!D7 -> 110200 | F19: ='MONTHLY P&L'!E7 -> 116280.47 | G19: ='MONTHLY P&L'!F7 -> 122680.56 | H19: ='MONTHLY P&L'!G7 -> 129416.65 | I19: ='MONTHLY P&L'!H7 -> 136505.94 | J19: ='MONTHLY P&L'!I7 -> 143966.49 | K19: ='MONTHLY P&L'!J7 -> 151817.29 | L19: ='MONTHLY P&L'!K7 -> 160078.26 | ... AB19: ='MONTHLY P&L'!AA7 -> 368863.05
C20: EBITDA | E20: ='MONTHLY P&L'!D27 -> -48396 | F20: ='MONTHLY P&L'!E27 -> -51639.837 | G20: ='MONTHLY P&L'!F27 -> -54739.892 | H20: ='MONTHLY P&L'!G27 -> -57686.082 | I20: ='MONTHLY P&L'!H27 -> -60467.775 | J20: ='MONTHLY P&L'!I27 -> -63073.771 | K20: ='MONTHLY P&L'!J27 -> -65492.266 | L20: ='MONTHLY P&L'!K27 -> -67710.822 | ... AB20: ='MONTHLY P&L'!AA27 -> -62836.186
C21: Cash | E21: ='CFS & SOFP'!D28 -> 1860131 | F21: ='CFS & SOFP'!E28 -> 1789179 | G21: ='CFS & SOFP'!F28 -> 1714767 | H21: ='CFS & SOFP'!G28 -> 1637036.6 | I21: ='CFS & SOFP'!H28 -> 1556139.3 | J21: ='CFS & SOFP'!I28 -> 1472237.4 | K21: ='CFS & SOFP'!J28 -> 1385504.5 | L21: ='CFS & SOFP'!K28 -> 1296125.7 | ... AB21: ='CFS & SOFP'!AA28 -> -285653.68
C22: Paid Traffic | E22: ='CUSTOMER ACQUISITION & REVENUE'!D9 -> 3000 | F22: ='CUSTOMER ACQUISITION & REVENUE'!E9 -> 3103.0982 | G22: ='CUSTOMER ACQUISITION & REVENUE'!F9 -> 3209.7396 | H22: ='CUSTOMER ACQUISITION & REVENUE'!G9 -> 3320.0458 | I22: ='CUSTOMER ACQUISITION & REVENUE'!H9 -> 3434.1427 | J22: ='CUSTOMER ACQUISITION & REVENUE'!I9 -> 3552.1608 | K22: ='CUSTOMER ACQUISITION & REVENUE'!J9 -> 3674.2346 | L22: ='CUSTOMER ACQUISITION & REVENUE'!K9 -> 3800.5037 | ... AB22: ='CUSTOMER ACQUISITION & REVENUE'!AA9 -> 6525.736
C23: Organic Traffic | E23: ='CUSTOMER ACQUISITION & REVENUE'!D10 -> 2000 | F23: ='CUSTOMER ACQUISITION & REVENUE'!E10 -> 2089.3518 | G23: ='CUSTOMER ACQUISITION & REVENUE'!F10 -> 2182.6955 | H23: ='CUSTOMER ACQUISITION & REVENUE'!G10 -> 2280.2094 | I23: ='CUSTOMER ACQUISITION & REVENUE'!H10 -> 2382.0798 | J23: ='CUSTOMER ACQUISITION & REVENUE'!I10 -> 2488.5014 | K23: ='CUSTOMER ACQUISITION & REVENUE'!J10 -> 2599.6775 | L23: ='CUSTOMER ACQUISITION & REVENUE'!K10 -> 2715.8204 | ... AB23: ='CUSTOMER ACQUISITION & REVENUE'!AA10 -> 5465.2033
